Workbook

Sheet Projects
A1: Project ID | B1: Project Name | C1: Program | D1: Theme | E1: Portfolio Category | F1: Business Unit | G1: Sponsor | H1: Delivery Lead | I1: PM | J1: Priority | K1: Investment Type | L1: Delivery Method | M1: Funding Type | N1: Governance Channel | O1: Financial Year | P1: Start Date | Q1: End Date | R1: Go Live Date | S1: Progress % | T1: Approved Funding | U1: CAPEX | V1: OPEX | W1: Total Funding | X1: Actual Spend | Y1: Forecast At Completion | Z1: Remaining Budget | AA1: Forecast Variance | AB1: Contingency | AC1: Benefits Forecast | AD1: Benefits Realised | AE1: Benefits Remaining | AF1: Benefit Realisation % | AG1: Budget | AH1: Actual Cost | AI1: Forecast | AJ1: Status | AK1: RAG
A2: PRJ001 | B2: Customer Portal | C2: Digital Transformation | D2: Digital & Applications | E2: Business Strategic | F2: Wholesale | G2: CTO | H2: Alex Brown | I2: John Smith | J2: P2 - High | K2: Transform | L2: Hybrid | M2: CAPEX | N2: Channel B (>$200K) | O2: FY25-26 | P2: 45702 | Q2: 46094 | R2: 46067 | S2: 74 | T2: 2593765 | U2: 1319588 | V2: 1274177 | W2: =U2+V2 | X2: 937070 | Y2: 2407335 | Z2: =T2-X2 | AA2: =T2-Y2 | AB2: 259376 | AC2: 6550938 | AD2: 2659810 | AE2: =AC2-AD2 | AF2: =IFERROR(AD2/AC2,0) | AG2: 2593765 | AH2: 937070 | AI2: 2407335 | AJ2: Completed | AK2: Green
A3: PRJ002 | B3: Cloud Migration | C3: Digital Transformation | D3: Cyber Security | E3: CAPEX | F3: Retail | G3: COO | H3: Carlos Diaz | I3: Mike Johnson | J3: P3 - Medium | K3: Run | L3: Agile | M3: CAPEX | N3: Channel B (>$200K) | O3: FY25 | P3: 45737 | Q3: 45937 | R3: 45889 | S3: 40 | T3: 1851915 | U3: 1106272 | V3: 745643 | W3: =U3+V3 | X3: 1714568 | Y3: 2065964 | Z3: =T3-X3 | AA3: =T3-Y3 | AB3: 185192 | AC3: 2754514 | AD3: 698458 | AE3: =AC3-AD3 | AF3: =IFERROR(AD3/AC3,0) | AG3: 1851915 | AH3: 1714568 | AI3: 2065964 | AJ3: Pipeline | AK3: Green
A4: PRJ003 | B4: Data Platform | C4: Cyber Security | D4: Data & Analytics | E4: Business Strategic | F4: Retail | G4: CFO | H4: Carlos Diaz | I4: John Smith | J4: P4 - Low | K4: Grow | L4: Agile | M4: Mixed | N4: Channel B (>$200K) | O4: FY25-26 | P4: 45756 | Q4: 46206 | R4: 46202 | S4: 78 | T4: 3895151 | U4: 2463632 | V4: 1431519 | W4: =U4+V4 | X4: 2432283 | Y4: 4441608 | Z4: =T4-X4 | AA4: =T4-Y4 | AB4: 389515 | AC4: 9010791 | AD4: 4658796 | AE4: =AC4-AD4 | AF4: =IFERROR(AD4/AC4,0) | AG4: 3895151 | AH4: 2432283 | AI4: 4441608 | AJ4: Active | AK4: Green
A5: PRJ004 | B5: AI Assistant | C5: Data & AI | D5: Data & Analytics | E5: IT Strategic | F5: HR | G5: CTO | H5: Jane Doe | I5: Priya Patel | J5: P3 - Medium | K5: Run | L5: Waterfall | M5: OPEX | N5: Channel B (>$200K) | O5: FY25-27 | P5: 45931 | Q5: 46394 | R5: 46379 | S5: 26 | T5: 1543706 | U5: 885049 | V5: 658657 | W5: =U5+V5 | X5: 545899 | Y5: 1818222 | Z5: =T5-X5 | AA5: =T5-Y5 | AB5: 154371 | AC5: 3653124 | AD5: 1335139 | AE5: =AC5-AD5 | AF5: =IFERROR(AD5/AC5,0) | AG5: 1543706 | AH5: 545899 | AI5: 1818222 | AJ5: Active | AK5: Green
A6: PRJ005 | B6: Network Refresh | C6: Cyber Security | D6: Data & Analytics | E6: Unfunded | F6: Wholesale | G6: CFO | H6: Priya Patel | I6: Alex Brown | J6: P3 - Medium | K6: Transform | L6: Hybrid | M6: Unfunded | N6: Channel B (>$200K) | O6: FY25-27 | P6: 45860 | Q6: 46402 | R6: 46344 | S6: 68 | T6: 1664543 | U6: 870832 | V6: 793711 | W6: =U6+V6 | X6: 1610411 | Y6: 1745295 | Z6: =T6-X6 | AA6: =T6-Y6 | AB6: 166454 | AC6: 4148450 | AD6: 529242 | AE6: =AC6-AD6 | AF6: =IFERROR(AD6/AC6,0) | AG6: 1664543 | AH6: 1610411 | AI6: 1745295 | AJ6: Completed | AK6: Amber
A7: PRJ006 | B7: Cyber Security Program | C7: Customer Experience | D7: Infrastructure | E7: Unfunded | F7: Technology | G7: CMO | H7: Alex Brown | I7: Sarah Lee | J7: P3 - Medium | K7: Transform | L7: Waterfall | M7: Unfunded | N7: Channel B (>$200K) | O7: FY25-26 | P7: 45736 | Q7: 46147 | R7: 46137 | S7: 19 | T7: 1657662 | U7: 956077 | V7: 701585 | W7: =U7+V7 | X7: 1736667 | Y7: 1704631 | Z7: =T7-X7 | AA7: =T7-Y7 | AB7: 165766 | AC7: 2260449 | AD7: 63902 | AE7: =AC7-AD7 | AF7: =IFERROR(AD7/AC7,0) | AG7: 1657662 | AH7: 1736667 | AI7: 1704631 | AJ7: Active | AK7: Red
A8: PRJ007 | B8: CRM Upgrade | C8: Digital Transformation | D8: Data & Analytics | E8: IT Strategic | F8: Marketing | G8: CTO | H8: Alex Brown | I8: Jane Doe | J8: P2 - High | K8: Grow | L8: Waterfall | M8: Mixed | N8: Channel B (>$200K) | O8: FY25-26 | P8: 45792 | Q8: 46379 | R8: 46347 | S8: 5 | T8: 3550675 | U8: 2708481 | V8: 842194 | W8: =U8+V8 | X8: 2947660 | Y8: 3440822 | Z8: =T8-X8 | AA8: =T8-Y8 | AB8: 355068 | AC8: 6136632 | AD8: 582334 | AE8: =AC8-AD8 | AF8: =IFERROR(AD8/AC8,0) | AG8: 3550675 | AH8: 2947660 | AI8: 3440822 | AJ8: Pipeline | AK8: Amber
A9: PRJ008 | B9: Mobile App | C9: Data & AI | D9: Infrastructure | E9: Business Strategic | F9: Marketing | G9: CTO | H9: Carlos Diaz | I9: Jane Doe | J9: P2 - High | K9: Transform | L9: Agile | M9: CAPEX | N9: Channel B (>$200K) | O9: FY25 | P9: 45780 | Q9: 45899 | R9: 45884 | S9: 44 | T9: 3682125 | U9: 2612949 | V9: 1069176 | W9: =U9+V9 | X9: 2077364 | Y9: 3273975 | Z9: =T9-X9 | AA9: =T9-Y9 | AB9: 368212 | AC9: 6824323 | AD9: 4034491 | AE9: =AC9-AD9 | AF9: =IFERROR(AD9/AC9,0) | AG9: 3682125 | AH9: 2077364 | AI9: 3273975 | AJ9: Pipeline | AK9: Green
A10: PRJ009 | B10: ERP Modernisation | C10: Customer Experience | D10: Cyber Security | E10: CAPEX | F10: Retail | G10: CFO | H10: Jane Doe | I10: John Smith | J10: P3 - Medium | K10: Run | L10: Hybrid | M10: OPEX | N10: Channel B (>$200K) | O10: FY26 | P10: 46023 | Q10: 46272 | R10: 46247 | S10: 30 | T10: 1133721 | U10: 913044 | V10: 220677 | W10: =U10+V10 | X10: 569106 | Y10: 1047705 | Z10: =T10-X10 | AA10: =T10-Y10 | AB10: 113372 | AC10: 2461006 | AD10: 1077819 | AE10: =AC10-AD10 | AF10: =IFERROR(AD10/AC10,0) | AG10: 1133721 | AH10: 569106 | AI10: 1047705 | AJ10: Pipeline | AK10: Green
A11: PRJ010 | B11: Workforce Enablement | C11: Data & AI | D11: Digital & Applications | E11: CAPEX | F11: Finance | G11: CFO | H11: Priya Patel | I11: Alex Brown | J11: P4 - Low | K11: Run | L11: Agile | M11: Mixed | N11: Channel B (>$200K) | O11: FY25-26 | P11: 45694 | Q11: 46047 | R11: 46032 | S11: 47 | T11: 2394916 | U11: 1203486 | V11: 1191430 | W11: =U11+V11 | X11: 1849950 | Y11: 2085028 | Z11: =T11-X11 | AA11: =T11-Y11 | AB11: 239492 | AC11: 3164452 | AD11: 59643 | AE11: =AC11-AD11 | AF11: =IFERROR(AD11/AC11,0) | AG11: 2394916 | AH11: 1849950 | AI11: 2085028 | AJ11: Completed | AK11: Green
A12: PRJ011 | B12: IoT Initiative | C12: Cloud Migration | D12: Infrastructure | E12: Unfunded | F12: Wholesale | G12: CFO | H12: Jane Doe | I12: Alex Brown | J12: P4 - Low | K12: Run | L12: Agile | M12: Unfunded | N12: Channel B (>$200K) | O12: FY25-26 | P12: 45988 | Q12: 46128 | R12: 46125 | S12: 88 | T12: 467871 | U12: 341847 | V12: 126024 | W12: =U12+V12 | X12: 204264 | Y12: 465010 | Z12: =T12-X12 | AA12: =T12-Y12 | AB12: 46787 | AC12: 1288941 | AD12: 41894 | AE12: =AC12-AD12 | AF12: =IFERROR(AD12/AC12,0) | AG12: 467871 | AH12: 204264 | AI12: 465010 | AJ12: Active | AK12: Green
A13: PRJ012 | B13: Analytics Platform | C13: Cyber Security | D13: Cyber Security | E13: Business Strategic | F13: Technology | G13: CMO | H13: Jane Doe | I13: Carlos Diaz | J13: P4 - Low | K13: Run | L13: Waterfall | M13: CAPEX | N13: Channel B (>$200K) | O13: FY25-27 | P13: 45934 | Q13: 46452 | R13: 46452 | S13: 88 | T13: 1904249 | U13: 1534958 | V13: 369291 | W13: =U13+V13 | X13: 326799 | Y13: 2157148 | Z13: =T13-X13 | AA13: =T13-Y13 | AB13: 190425 | AC13: 5219052 | AD13: 306594 | AE13: =AC13-AD13 | AF13: =IFERROR(AD13/AC13,0) | AG13: 1904249 | AH13: 326799 | AI13: 2157148 | AJ13: Completed | AK13: Green
... A41: PRJ040 | B41: Zero-Trust Net | C41: Customer Experience | D41: Digital & Applications | E41: CAPEX | F41: Technology | G41: CIO | H41: Alex Brown | I41: Jane Doe | J41: P2 - High | K41: Grow | L41: Waterfall | M41: Mixed | N41: Channel B (>$200K) | O41: FY25-26 | P41: 45694 | Q41: 46135 | R41: 46121 | S41: 63 | T41: 1693219 | U41: 1255149 | V41: 438070 | W41: =U41+V41 | X41: 925203 | Y41: 1458579 | Z41: =T41-X41 | AA41: =T41-Y41 | AB41: 169322 | AC41: 2909947 | AD41: 493617 | AE41: =AC41-AD41 | AF41: =IFERROR(AD41/AC41,0) | AG41: 1693219 | AH41: 925203 | AI41: 1458579 | AJ41: Active | AK41: Green

Sheet Roadmap
A1: Project ID | B1: Month | C1: Year | D1: Phase | E1: Status
A2: PRJ001 | B2: Mar | C2: 2025 | D2: Design | E2: Completed
A3: PRJ001 | B3: Apr | C3: 2025 | D3: Build | E3: Completed
A4: PRJ001 | B4: May | C4: 2025 | D4: Deploy | E4: Completed
A5: PRJ001 | B5: Jun | C5: 2025 | D5: Deploy | E5: Completed
A6: PRJ001 | B6: Jul | C6: 2025 | D6: Build | E6: Completed
A7: PRJ001 | B7: Aug | C7: 2025 | D7: Test | E7: Completed
A8: PRJ001 | B8: Sep | C8: 2025 | D8: Discovery | E8: Completed
A9: PRJ001 | B9: Oct | C9: 2025 | D9: Test | E9: Completed
A10: PRJ001 | B10: Nov | C10: 2025 | D10: Build | E10: Completed
A11: PRJ001 | B11: Dec | C11: 2025 | D11: Test | E11: Completed
A12: PRJ001 | B12: Jan | C12: 2026 | D12: Build | E12: Completed
A13: PRJ001 | B13: Feb | C13: 2026 | D13: Deploy | E13: Completed
... A483: PRJ040 | B483: Apr | C483: 2026 | D483: Build | E483: Active

Sheet Risks
A1: Risk ID | B1: Project ID | C1: Description | D1: Probability | E1: Impact | F1: Velocity | G1: Owner | H1: Mitigation Plan | I1: Status
A2: R001 | B2: PRJ028 | C2: Vendor delay impacting milestone | D2: Medium | E2: High | F2: Medium | G2: John Smith | H2: Increase staffing | I2: Open
A3: R002 | B3: PRJ010 | C3: Stakeholder alignment risk | D3: Low | E3: Low | F3: Medium | G3: Carlos Diaz | H3: Increase staffing | I3: Mitigated
A4: R003 | B4: PRJ008 | C4: Scope creep | D4: High | E4: Medium | F4: Medium | G4: Carlos Diaz | H4: Increase staffing | I4: Open
A5: R004 | B5: PRJ039 | C5: Scope creep | D5: Low | E5: Medium | F5: Medium | G5: Priya Patel | H5: Rebaseline budget | I5: Mitigated
A6: R005 | B6: PRJ023 | C6: Vendor delay impacting milestone | D6: Low | E6: Medium | F6: Fast | G6: Priya Patel | H6: Patch & monitoring | I6: Open
A7: R006 | B7: PRJ010 | C7: Vendor delay impacting milestone | D7: Low | E7: Medium | F7: Medium | G7: Sarah Lee | H7: Patch & monitoring | I7: Mitigated
A8: R007 | B8: PRJ011 | C8: Integration risk | D8: Medium | E8: High | F8: Fast | G8: Alex Brown | H8: Add buffer | I8: Open
A9: R008 | B9: PRJ010 | C9: Resource shortage | D9: High | E9: Low | F9: Fast | G9: John Smith | H9: Rebaseline budget | I9: Closed
A10: R009 | B10: PRJ028 | C10: Stakeholder alignment risk | D10: High | E10: Critical | F10: Medium | G10: Mike Johnson | H10: Engage vendor | I10: Open
A11: R010 | B11: PRJ023 | C11: Regulatory change | D11: Low | E11: High | F11: Fast | G11: Priya Patel | H11: Increase staffing | I11: Closed
A12: R011 | B12: PRJ034 | C12: Scope creep | D12: Low | E12: Medium | F12: Medium | G12: Alex Brown | H12: Add buffer | I12: Open
... A61: R060 | B61: PRJ026 | C61: Stakeholder alignment risk | D61: Medium | E61: High | F61: Slow | G61: Sarah Lee | H61: Stakeholder workshop | I61: Closed

Sheet RAID
A1: RAID ID | B1: Project ID | C1: Type | D1: Description | E1: Probability | F1: Impact | G1: RAG | H1: Owner | I1: Target Resolution Date | J1: Mitigation | K1: Status
A2: RAID001 | B2: PRJ024 | C2: Assumption | D2: Regulatory deadline | E2: Low | F2: Critical | G2: Green | H2: Sarah Lee | I2: 46236 | J2: Contingency plan | K2: Closed
A3: RAID002 | B3: PRJ019 | C3: Assumption | D3: Cloud provider outage risk | E3: Low | F3: High | G3: Red | H3: Mike Johnson | I3: 46160 | J3: Re-baseline | K3: Closed
A4: RAID003 | B4: PRJ028 | C4: Issue | D4: Staff turnover | E4: Medium | F4: High | G4: Amber | H4: John Smith | I4: 46268 | J4: Vendor escalation | K4: Closed
A5: RAID004 | B5: PRJ028 | C5: Assumption | D5: Staff turnover | E5: Low | F5: Low | G5: Red | H5: Priya Patel | I5: 46185 | J5: Vendor escalation | K5: Closed
A6: RAID005 | B6: PRJ011 | C6: Risk | D6: Test data not available | E6: High | F6: Critical | G6: Green | H6: Jane Doe | I6: 46099 | J6: Contingency plan | K6: Closed
A7: RAID006 | B7: PRJ024 | C7: Assumption | D7: Depends on procurement signoff | E7: High | F7: Low | G7: Red | H7: Jane Doe | I7: 46255 | J7: Re-baseline | K7: In Progress
A8: RAID007 | B8: PRJ024 | C8: Dependency | D8: Regulatory deadline | E8: Low | F8: Medium | G8: Red | H8: Mike Johnson | I8: 46183 | J8: Vendor escalation | K8: Closed
A9: RAID008 | B9: PRJ018 | C9: Issue | D9: Cloud provider outage risk | E9: Low | F9: Medium | G9: Amber | H9: Alex Brown | I9: 46181 | J9: Add buffer | K9: Open
A10: RAID009 | B10: PRJ017 | C10: Assumption | D10: Staff turnover | E10: Medium | F10: Medium | G10: Red | H10: Mike Johnson | I10: 46259 | J10: Re-baseline | K10: Open
A11: RAID010 | B11: PRJ008 | C11: Issue | D11: Regulatory deadline | E11: Low | F11: Critical | G11: Green | H11: Priya Patel | I11: 46195 | J11: Active monitoring | K11: Closed
A12: RAID011 | B12: PRJ021 | C12: Assumption | D12: Staff turnover | E12: Low | F12: High | G12: Amber | H12: Carlos Diaz | I12: 46122 | J12: Contingency plan | K12: In Progress
A13: RAID012 | B13: PRJ033 | C13: Issue | D13: Cloud provider outage risk | E13: Low | F13: Medium | G13: Green | H13: Carlos Diaz | I13: 46208 | J13: Active monitoring | K13: In Progress
... A81: RAID080 | B81: PRJ036 | C81: Issue | D81: Depends on procurement signoff | E81: Low | F81: High | G81: Amber | H81: John Smith | I81: 46136 | J81: Contingency plan | K81: Closed

Sheet StageGates
A1: Project ID | B1: Project Name | C1: Governance Channel | D1: Stage | E1: Next Gate | F1: Gate Status | G1: Status | H1: Gate Owner | I1: Planned Gate Date | J1: Actual Gate Date | K1: Gate Outcome | L1: Gate Comments | M1: Checklist Complete % | N1: Days Late | O1: _Key
A2: PRJ001 | B2: =IFERROR(VLOOKUP(A2,Projects!$A:$AK,2,FALSE()),"") | C2: =IFERROR(VLOOKUP(A2,Projects!$A:$AK,14,FALSE()),"") | D2: Discovery | E2: =IFERROR(INDEX(_Stages!$A$1:$A$8,MIN(MATCH(D2,_Stages!$A$1:$A$8,0)+1,8)),"") | F2: Approved | G2: Complete | H2: CTO | I2: 45702 | J2: 45717 | K2: Conditional | L2: Approved with conditions | M2: 100 | N2: 15 | O2: =A2&"|"&D2
A3: PRJ001 | B3: =IFERROR(VLOOKUP(A3,Projects!$A:$AK,2,FALSE()),"") | C3: =IFERROR(VLOOKUP(A3,Projects!$A:$AK,14,FALSE()),"") | D3: Business Case / Seed Funding | E3: =IFERROR(INDEX(_Stages!$A$1:$A$8,MIN(MATCH(D3,_Stages!$A$1:$A$8,0)+1,8)),"") | F3: Pending Approval | G3: In Progress | H3: CTO | I3: 45762 | L3: Awaiting sponsor sign-off | M3: 89 | N3: 0 | O3: =A3&"|"&D3
A4: PRJ001 | B4: =IFERROR(VLOOKUP(A4,Projects!$A:$AK,2,FALSE()),"") | C4: =IFERROR(VLOOKUP(A4,Projects!$A:$AK,14,FALSE()),"") | D4: Design | E4: =IFERROR(INDEX(_Stages!$A$1:$A$8,MIN(MATCH(D4,_Stages!$A$1:$A$8,0)+1,8)),"") | F4: Not Started | G4: Not Started | H4: CTO | I4: 45822 | L4: On track | M4: 0 | N4: 0 | O4: =A4&"|"&D4
A5: PRJ001 | B5: =IFERROR(VLOOKUP(A5,Projects!$A:$AK,2,FALSE()),"") | C5: =IFERROR(VLOOKUP(A5,Projects!$A:$AK,14,FALSE()),"") | D5: Business Case / Full Funding | E5: =IFERROR(INDEX(_Stages!$A$1:$A$8,MIN(MATCH(D5,_Stages!$A$1:$A$8,0)+1,8)),"") | F5: Not Started | G5: Not Started | H5: CTO | I5: 45882 | L5: Awaiting sponsor sign-off | M5: 0 | N5: 0 | O5: =A5&"|"&D5
A6: PRJ001 | B6: =IFERROR(VLOOKUP(A6,Projects!$A:$AK,2,FALSE()),"") | C6: =IFERROR(VLOOKUP(A6,Projects!$A:$AK,14,FALSE()),"") | D6: Build | E6: =IFERROR(INDEX(_Stages!$A$1:$A$8,MIN(MATCH(D6,_Stages!$A$1:$A$8,0)+1,8)),"") | F6: Not Started | G6: Not Started | H6: CTO | I6: 45942 | L6: Awaiting sponsor sign-off | M6: 0 | N6: 0 | O6: =A6&"|"&D6
A7: PRJ001 | B7: =IFERROR(VLOOKUP(A7,Projects!$A:$AK,2,FALSE()),"") | C7: =IFERROR(VLOOKUP(A7,Projects!$A:$AK,14,FALSE()),"") | D7: Testing | E7: =IFERROR(INDEX(_Stages!$A$1:$A$8,MIN(MATCH(D7,_Stages!$A$1:$A$8,0)+1,8)),"") | F7: Not Started | G7: Not Started | H7: CTO | I7: 46002 | L7: On track | M7: 0 | N7: 0 | O7: =A7&"|"&D7
A8: PRJ001 | B8: =IFERROR(VLOOKUP(A8,Projects!$A:$AK,2,FALSE()),"") | C8: =IFERROR(VLOOKUP(A8,Projects!$A:$AK,14,FALSE()),"") | D8: Deployment | E8: =IFERROR(INDEX(_Stages!$A$1:$A$8,MIN(MATCH(D8,_Stages!$A$1:$A$8,0)+1,8)),"") | F8: Not Started | G8: Not Started | H8: CTO | I8: 46062 | M8: 0 | N8: 0 | O8: =A8&"|"&D8
A9: PRJ001 | B9: =IFERROR(VLOOKUP(A9,Projects!$A:$AK,2,FALSE()),"") | C9: =IFERROR(VLOOKUP(A9,Projects!$A:$AK,14,FALSE()),"") | D9: Handover | E9: =IFERROR(INDEX(_Stages!$A$1:$A$8,MIN(MATCH(D9,_Stages!$A$1:$A$8,0)+1,8)),"") | F9: Not Started | G9: Not Started | H9: CTO | I9: 46122 | L9: Awaiting sponsor sign-off | M9: 0 | N9: 0 | O9: =A9&"|"&D9
A10: PRJ002 | B10: =IFERROR(VLOOKUP(A10,Projects!$A:$AK,2,FALSE()),"") | C10: =IFERROR(VLOOKUP(A10,Projects!$A:$AK,14,FALSE()),"") | D10: Discovery | E10: =IFERROR(INDEX(_Stages!$A$1:$A$8,MIN(MATCH(D10,_Stages!$A$1:$A$8,0)+1,8)),"") | F10: Approved | G10: Complete | H10: COO | I10: 45737 | J10: 45745 | K10: Rework | L10: On track | M10: 100 | N10: 8 | O10: =A10&"|"&D10
A11: PRJ002 | B11: =IFERROR(VLOOKUP(A11,Projects!$A:$AK,2,FALSE()),"") | C11: =IFERROR(VLOOKUP(A11,Projects!$A:$AK,14,FALSE()),"") | D11: Business Case / Seed Funding | E11: =IFERROR(INDEX(_Stages!$A$1:$A$8,MIN(MATCH(D11,_Stages!$A$1:$A$8,0)+1,8)),"") | F11: Approved | G11: Complete | H11: COO | I11: 45797 | J11: 45784 | K11: Conditional | L11: Approved with conditions | M11: 100 | N11: 0 | O11: =A11&"|"&D11
A12: PRJ002 | B12: =IFERROR(VLOOKUP(A12,Projects!$A:$AK,2,FALSE()),"") | C12: =IFERROR(VLOOKUP(A12,Projects!$A:$AK,14,FALSE()),"") | D12: Design | E12: =IFERROR(INDEX(_Stages!$A$1:$A$8,MIN(MATCH(D12,_Stages!$A$1:$A$8,0)+1,8)),"") | F12: Approved | G12: Complete | H12: COO | I12: 45857 | J12: 45843 | K12: Rework | L12: On track | M12: 100 | N12: 0 | O12: =A12&"|"&D12
A13: PRJ002 | B13: =IFERROR(VLOOKUP(A13,Projects!$A:$AK,2,FALSE()),"") | C13: =IFERROR(VLOOKUP(A13,Projects!$A:$AK,14,FALSE()),"") | D13: Business Case / Full Funding | E13: =IFERROR(INDEX(_Stages!$A$1:$A$8,MIN(MATCH(D13,_Stages!$A$1:$A$8,0)+1,8)),"") | F13: Pending Approval | G13: In Progress | H13: COO | I13: 45917 | L13: Approved with conditions | M13: 61 | N13: 0 | O13: =A13&"|"&D13
A14: PRJ002 | B14: =IFERROR(VLOOKUP(A14,Projects!$A:$AK,2,FALSE()),"") | C14: =IFERROR(VLOOKUP(A14,Projects!$A:$AK,14,FALSE()),"") | D14: Build | E14: =IFERROR(INDEX(_Stages!$A$1:$A$8,MIN(MATCH(D14,_Stages!$A$1:$A$8,0)+1,8)),"") | F14: Not Started | G14: Not Started | H14: COO | I14: 45977 | L14: On track | M14: 0 | N14: 0 | O14: =A14&"|"&D14
A15: PRJ002 | B15: =IFERROR(VLOOKUP(A15,Projects!$A:$AK,2,FALSE()),"") | C15: =IFERROR(VLOOKUP(A15,Projects!$A:$AK,14,FALSE()),"") | D15: Testing | E15: =IFERROR(INDEX(_Stages!$A$1:$A$8,MIN(MATCH(D15,_Stages!$A$1:$A$8,0)+1,8)),"") | F15: Not Started | G15: Not Started | H15: COO | I15: 46037 | L15: Approved with conditions | M15: 0 | N15: 0 | O15: =A15&"|"&D15
A16: PRJ002 | B16: =IFERROR(VLOOKUP(A16,Projects!$A:$AK,2,FALSE()),"") | C16: =IFERROR(VLOOKUP(A16,Projects!$A:$AK,14,FALSE()),"") | D16: Deployment | E16: =IFERROR(INDEX(_Stages!$A$1:$A$8,MIN(MATCH(D16,_Stages!$A$1:$A$8,0)+1,8)),"") | F16: Not Started | G16: Not Started | H16: COO | I16: 46097 | L16: Awaiting sponsor sign-off | M16: 0 | N16: 0 | O16: =A16&"|"&D16
A17: PRJ002 | B17: =IFERROR(VLOOKUP(A17,Projects!$A:$AK,2,FALSE()),"") | C17: =IFERROR(VLOOKUP(A17,Projects!$A:$AK,14,FALSE()),"") | D17: Handover | E17: =IFERROR(INDEX(_Stages!$A$1:$A$8,MIN(MATCH(D17,_Stages!$A$1:$A$8,0)+1,8)),"") | F17: Not Started | G17: Not Started | H17: COO | I17: 46157 | L17: On track | M17: 0 | N17: 0 | O17: =A17&"|"&D17
A18: PRJ003 | B18: =IFERROR(VLOOKUP(A18,Projects!$A:$AK,2,FALSE()),"") | C18: =IFERROR(VLOOKUP(A18,Projects!$A:$AK,14,FALSE()),"") | D18: Discovery | E18: =IFERROR(INDEX(_Stages!$A$1:$A$8,MIN(MATCH(D18,_Stages!$A$1:$A$8,0)+1,8)),"") | F18: Approved | G18: Complete | H18: CFO | I18: 45756 | J18: 45770 | K18: Conditional | L18: Awaiting sponsor sign-off | M18: 100 | N18: 14 | O18: =A18&"|"&D18
A19: PRJ003 | B19: =IFERROR(VLOOKUP(A19,Projects!$A:$AK,2,FALSE()),"") | C19: =IFERROR(VLOOKUP(A19,Projects!$A:$AK,14,FALSE()),"") | D19: Business Case / Seed Funding | E19: =IFERROR(INDEX(_Stages!$A$1:$A$8,MIN(MATCH(D19,_Stages!$A$1:$A$8,0)+1,8)),"") | F19: Approved | G19: Complete | H19: CFO | I19: 45816 | J19: 45811 | K19: Conditional | L19: On track | M19: 100 | N19: 0 | O19: =A19&"|"&D19
A20: PRJ003 | B20: =IFERROR(VLOOKUP(A20,Projects!$A:$AK,2,FALSE()),"") | C20: =IFERROR(VLOOKUP(A20,Projects!$A:$AK,14,FALSE()),"") | D20: Design | E20: =IFERROR(INDEX(_Stages!$A$1:$A$8,MIN(MATCH(D20,_Stages!$A$1:$A$8,0)+1,8)),"") | F20: Approved | G20: Complete | H20: CFO | I20: 45876 | J20: 45872 | K20: Proceed | M20: 100 | N20: 0 | O20: =A20&"|"&D20
A21: PRJ003 | B21: =IFERROR(VLOOKUP(A21,Projects!$A:$AK,2,FALSE()),"") | C21: =IFERROR(VLOOKUP(A21,Projects!$A:$AK,14,FALSE()),"") | D21: Business Case / Full Funding | E21: =IFERROR(INDEX(_Stages!$A$1:$A$8,MIN(MATCH(D21,_Stages!$A$1:$A$8,0)+1,8)),"") | F21: Approved | G21: Complete | H21: CFO | I21: 45936 | J21: 45925 | K21: Proceed | M21: 100 | N21: 0 | O21: =A21&"|"&D21
A22: PRJ003 | B22: =IFERROR(VLOOKUP(A22,Projects!$A:$AK,2,FALSE()),"") | C22: =IFERROR(VLOOKUP(A22,Projects!$A:$AK,14,FALSE()),"") | D22: Build | E22: =IFERROR(INDEX(_Stages!$A$1:$A$8,MIN(MATCH(D22,_Stages!$A$1:$A$8,0)+1,8)),"") | F22: Approved | G22: Complete | H22: CFO | I22: 45996 | J22: 46007 | K22: Conditional | L22: Approved with conditions | M22: 100 | N22: 11 | O22: =A22&"|"&D22
A23: PRJ003 | B23: =IFERROR(VLOOKUP(A23,Projects!$A:$AK,2,FALSE()),"") | C23: =IFERROR(VLOOKUP(A23,Projects!$A:$AK,14,FALSE()),"") | D23: Testing | E23: =IFERROR(INDEX(_Stages!$A$1:$A$8,MIN(MATCH(D23,_Stages!$A$1:$A$8,0)+1,8)),"") | F23: Approved | G23: Complete | H23: CFO | I23: 46056 | J23: 46045 | K23: Conditional | M23: 100 | N23: 0 | O23: =A23&"|"&D23
A24: PRJ003 | B24: =IFERROR(VLOOKUP(A24,Projects!$A:$AK,2,FALSE()),"") | C24: =IFERROR(VLOOKUP(A24,Projects!$A:$AK,14,FALSE()),"") | D24: Deployment | E24: =IFERROR(INDEX(_Stages!$A$1:$A$8,MIN(MATCH(D24,_Stages!$A$1:$A$8,0)+1,8)),"") | F24: Approved | G24: Complete | H24: CFO | I24: 46116 | J24: 46114 | K24: Held | L24: Awaiting sponsor sign-off | M24: 100 | N24: 0 | O24: =A24&"|"&D24
A25: PRJ003 | B25: =IFERROR(VLOOKUP(A25,Projects!$A:$AK,2,FALSE()),"") | C25: =IFERROR(VLOOKUP(A25,Projects!$A:$AK,14,FALSE()),"") | D25: Handover | E25: =IFERROR(INDEX(_Stages!$A$1:$A$8,MIN(MATCH(D25,_Stages!$A$1:$A$8,0)+1,8)),"") | F25: In Progress | G25: In Progress | H25: CFO | I25: 46176 | L25: On track | M25: 41 | N25: 0 | O25: =A25&"|"&D25
A26: PRJ004 | B26: =IFERROR(VLOOKUP(A26,Projects!$A:$AK,2,FALSE()),"") | C26: =IFERROR(VLOOKUP(A26,Projects!$A:$AK,14,FALSE()),"") | D26: Discovery | E26: =IFERROR(INDEX(_Stages!$A$1:$A$8,MIN(MATCH(D26,_Stages!$A$1:$A$8,0)+1,8)),"") | F26: In Progress | G26: In Progress | H26: CTO | I26: 45931 | M26: 41 | N26: 0 | O26: =A26&"|"&D26
A27: PRJ004 | B27: =IFERROR(VLOOKUP(A27,Projects!$A:$AK,2,FALSE()),"") | C27: =IFERROR(VLOOKUP(A27,Projects!$A:$AK,14,FALSE()),"") | D27: Business Case / Seed Funding | E27: =IFERROR(INDEX(_Stages!$A$1:$A$8,MIN(MATCH(D27,_Stages!$A$1:$A$8,0)+1,8)),"") | F27: Not Started | G27: Not Started | H27: CTO | I27: 45991 | L27: Awaiting sponsor sign-off | M27: 0 | N27: 0 | O27: =A27&"|"&D27
A28: PRJ004 | B28: =IFERROR(VLOOKUP(A28,Projects!$A:$AK,2,FALSE()),"") | C28: =IFERROR(VLOOKUP(A28,Projects!$A:$AK,14,FALSE()),"") | D28: Design | E28: =IFERROR(INDEX(_Stages!$A$1:$A$8,MIN(MATCH(D28,_Stages!$A$1:$A$8,0)+1,8)),"") | F28: Not Started | G28: Not Started | H28: CTO | I28: 46051 | L28: Awaiting sponsor sign-off | M28: 0 | N28: 0 | O28: =A28&"|"&D28
A29: PRJ004 | B29: =IFERROR(VLOOKUP(A29,Projects!$A:$AK,2,FALSE()),"") | C29: =IFERROR(VLOOKUP(A29,Projects!$A:$AK,14,FALSE()),"") | D29: Business Case / Full Funding | E29: =IFERROR(INDEX(_Stages!$A$1:$A$8,MIN(MATCH(D29,_Stages!$A$1:$A$8,0)+1,8)),"") | F29: Not Started | G29: Not Started | H29: CTO | I29: 46111 | L29: On track | M29: 0 | N29: 0 | O29: =A29&"|"&D29
A30: PRJ004 | B30: =IFERROR(VLOOKUP(A30,Projects!$A:$AK,2,FALSE()),"") | C30: =IFERROR(VLOOKUP(A30,Projects!$A:$AK,14,FALSE()),"") | D30: Build | E30: =IFERROR(INDEX(_Stages!$A$1:$A$8,MIN(MATCH(D30,_Stages!$A$1:$A$8,0)+1,8)),"") | F30: Not Started | G30: Not Started | H30: CTO | I30: 46171 | M30: 0 | N30: 0 | O30: =A30&"|"&D30
A31: PRJ004 | B31: =IFERROR(VLOOKUP(A31,Projects!$A:$AK,2,FALSE()),"") | C31: =IFERROR(VLOOKUP(A31,Projects!$A:$AK,14,FALSE()),"") | D31: Testing | E31: =IFERROR(INDEX(_Stages!$A$1:$A$8,MIN(MATCH(D31,_Stages!$A$1:$A$8,0)+1,8)),"") | F31: Not Started | G31: Not Started | H31: CTO | I31: 46231 | L31: Approved with conditions | M31: 0 | N31: 0 | O31: =A31&"|"&D31
A32: PRJ004 | B32: =IFERROR(VLOOKUP(A32,Projects!$A:$AK,2,FALSE()),"") | C32: =IFERROR(VLOOKUP(A32,Projects!$A:$AK,14,FALSE()),"") | D32: Deployment | E32: =IFERROR(INDEX(_Stages!$A$1:$A$8,MIN(MATCH(D32,_Stages!$A$1:$A$8,0)+1,8)),"") | F32: Not Started | G32: Not Started | H32: CTO | I32: 46291 | L32: Approved with conditions | M32: 0 | N32: 0 | O32: =A32&"|"&D32
A33: PRJ004 | B33: =IFERROR(VLOOKUP(A33,Projects!$A:$AK,2,FALSE()),"") | C33: =IFERROR(VLOOKUP(A33,Projects!$A:$AK,14,FALSE()),"") | D33: Handover | E33: =IFERROR(INDEX(_Stages!$A$1:$A$8,MIN(MATCH(D33,_Stages!$A$1:$A$8,0)+1,8)),"") | F33: Not Started | G33: Not Started | H33: CTO | I33: 46351 | L33: Awaiting sponsor sign-off | M33: 0 | N33: 0 | O33: =A33&"|"&D33
A34: PRJ005 | B34: =IFERROR(VLOOKUP(A34,Projects!$A:$AK,2,FALSE()),"") | C34: =IFERROR(VLOOKUP(A34,Projects!$A:$AK,14,FALSE()),"") | D34: Discovery | E34: =IFERROR(INDEX(_Stages!$A$1:$A$8,MIN(MATCH(D34,_Stages!$A$1:$A$8,0)+1,8)),"") | F34: Approved | G34: Complete | H34: CFO | I34: 45860 | J34: 45862 | K34: Held | M34: 100 | N34: 2 | O34: =A34&"|"&D34
A35: PRJ005 | B35: =IFERROR(VLOOKUP(A35,Projects!$A:$AK,2,FALSE()),"") | C35: =IFERROR(VLOOKUP(A35,Projects!$A:$AK,14,FALSE()),"") | D35: Business Case / Seed Funding | E35: =IFERROR(INDEX(_Stages!$A$1:$A$8,MIN(MATCH(D35,_Stages!$A$1:$A$8,0)+1,8)),"") | F35: Approved | G35: Complete | H35: CFO | I35: 45920 | J35: 45928 | K35: Held | L35: On track | M35: 100 | N35: 8 | O35: =A35&"|"&D35
A36: PRJ005 | B36: =IFERROR(VLOOKUP(A36,Projects!$A:$AK,2,FALSE()),"") | C36: =IFERROR(VLOOKUP(A36,Projects!$A:$AK,14,FALSE()),"") | D36: Design | E36: =IFERROR(INDEX(_Stages!$A$1:$A$8,MIN(MATCH(D36,_Stages!$A$1:$A$8,0)+1,8)),"") | F36: Approved | G36: Complete | H36: CFO | I36: 45980 | J36: 46001 | K36: Conditional | L36: Approved with conditions | M36: 100 | N36: 21 | O36: =A36&"|"&D36
A37: PRJ005 | B37: =IFERROR(VLOOKUP(A37,Projects!$A:$AK,2,FALSE()),"") | C37: =IFERROR(VLOOKUP(A37,Projects!$A:$AK,14,FALSE()),"") | D37: Business Case / Full Funding | E37: =IFERROR(INDEX(_Stages!$A$1:$A$8,MIN(MATCH(D37,_Stages!$A$1:$A$8,0)+1,8)),"") | F37: Approved | G37: Complete | H37: CFO | I37: 46040 | J37: 46044 | K37: Proceed | M37: 100 | N37: 4 | O37: =A37&"|"&D37
A38: PRJ005 | B38: =IFERROR(VLOOKUP(A38,Projects!$A:$AK,2,FALSE()),"") | C38: =IFERROR(VLOOKUP(A38,Projects!$A:$AK,14,FALSE()),"") | D38: Build | E38: =IFERROR(INDEX(_Stages!$A$1:$A$8,MIN(MATCH(D38,_Stages!$A$1:$A$8,0)+1,8)),"") | F38: Approved | G38: Complete | H38: CFO | I38: 46100 | J38: 46090 | K38: Held | L38: On track | M38: 100 | N38: 0 | O38: =A38&"|"&D38
A39: PRJ005 | B39: =IFERROR(VLOOKUP(A39,Projects!$A:$AK,2,FALSE()),"") | C39: =IFERROR(VLOOKUP(A39,Projects!$A:$AK,14,FALSE()),"") | D39: Testing | E39: =IFERROR(INDEX(_Stages!$A$1:$A$8,MIN(MATCH(D39,_Stages!$A$1:$A$8,0)+1,8)),"") | F39: In Progress | G39: In Progress | H39: CFO | I39: 46160 | M39: 80 | N39: 0 | O39: =A39&"|"&D39
A40: PRJ005 | B40: =IFERROR(VLOOKUP(A40,Projects!$A:$AK,2,FALSE()),"") | C40: =IFERROR(VLOOKUP(A40,Projects!$A:$AK,14,FALSE()),"") | D40: Deployment | E40: =IFERROR(INDEX(_Stages!$A$1:$A$8,MIN(MATCH(D40,_Stages!$A$1:$A$8,0)+1,8)),"") | F40: Not Started | G40: Not Started | H40: CFO | I40: 46220 | L40: Approved with conditions | M40: 0 | N40: 0 | O40: =A40&"|"&D40
...

Sheet Financials
A1: Project ID | B1: Month | C1: CAPEX | D1: OPEX | E1: Actual | F1: Forecast | G1: Variance | H1: Planned Value | I1: Earned Value
A2: PRJ001 | B2: Jan | C2: =IFERROR(VLOOKUP(A2,Projects!$A:$AK,21,FALSE())/12,0) | D2: =IFERROR(VLOOKUP(A2,Projects!$A:$AK,22,FALSE())/12,0) | E2: 261933 | F2: 301306 | G2: =F2-E2 | H2: 251156 | I2: 195289
A3: PRJ001 | B3: Feb | C3: =IFERROR(VLOOKUP(A3,Projects!$A:$AK,21,FALSE())/12,0) | D3: =IFERROR(VLOOKUP(A3,Projects!$A:$AK,22,FALSE())/12,0) | E3: 231778 | F3: 225033 | G3: =F3-E3 | H3: 192576 | I3: 147431
A4: PRJ001 | B4: Mar | C4: =IFERROR(VLOOKUP(A4,Projects!$A:$AK,21,FALSE())/12,0) | D4: =IFERROR(VLOOKUP(A4,Projects!$A:$AK,22,FALSE())/12,0) | E4: 174362 | F4: 182142 | G4: =F4-E4 | H4: 135066 | I4: 165831
A5: PRJ001 | B5: Apr | C5: =IFERROR(VLOOKUP(A5,Projects!$A:$AK,21,FALSE())/12,0) | D5: =IFERROR(VLOOKUP(A5,Projects!$A:$AK,22,FALSE())/12,0) | E5: 272440 | F5: 283263 | G5: =F5-E5 | H5: 203135 | I5: 213717
A6: PRJ001 | B6: May | C6: =IFERROR(VLOOKUP(A6,Projects!$A:$AK,21,FALSE())/12,0) | D6: =IFERROR(VLOOKUP(A6,Projects!$A:$AK,22,FALSE())/12,0) | E6: 237193 | F6: 204783 | G6: =F6-E6 | H6: 223895 | I6: 154098
A7: PRJ001 | B7: Jun | C7: =IFERROR(VLOOKUP(A7,Projects!$A:$AK,21,FALSE())/12,0) | D7: =IFERROR(VLOOKUP(A7,Projects!$A:$AK,22,FALSE())/12,0) | E7: 222203 | F7: 317214 | G7: =F7-E7 | H7: 276980 | I7: 191631
A8: PRJ001 | B8: Jul | C8: =IFERROR(VLOOKUP(A8,Projects!$A:$AK,21,FALSE())/12,0) | D8: =IFERROR(VLOOKUP(A8,Projects!$A:$AK,22,FALSE())/12,0) | E8: 245586 | F8: 292094 | G8: =F8-E8 | H8: 208528 | I8: 227833
A9: PRJ001 | B9: Aug | C9: =IFERROR(VLOOKUP(A9,Projects!$A:$AK,21,FALSE())/12,0) | D9: =IFERROR(VLOOKUP(A9,Projects!$A:$AK,22,FALSE())/12,0) | E9: 239886 | F9: 257711 | G9: =F9-E9 | H9: 271464 | I9: 259232
A10: PRJ001 | B10: Sep | C10: =IFERROR(VLOOKUP(A10,Projects!$A:$AK,21,FALSE())/12,0) | D10: =IFERROR(VLOOKUP(A10,Projects!$A:$AK,22,FALSE())/12,0) | E10: 164832 | F10: 179916 | G10: =F10-E10 | H10: 165087 | I10: 134079
A11: PRJ001 | B11: Oct | C11: =IFERROR(VLOOKUP(A11,Projects!$A:$AK,21,FALSE())/12,0) | D11: =IFERROR(VLOOKUP(A11,Projects!$A:$AK,22,FALSE())/12,0) | E11: 175825 | F11: 157796 | G11: =F11-E11 | H11: 137163 | I11: 147237
A12: PRJ001 | B12: Nov | C12: =IFERROR(VLOOKUP(A12,Projects!$A:$AK,21,FALSE())/12,0) | D12: =IFERROR(VLOOKUP(A12,Projects!$A:$AK,22,FALSE())/12,0) | E12: 227590 | F12: 270516 | G12: =F12-E12 | H12: 274054 | I12: 288863
A13: PRJ001 | B13: Dec | C13: =IFERROR(VLOOKUP(A13,Projects!$A:$AK,21,FALSE())/12,0) | D13: =IFERROR(VLOOKUP(A13,Projects!$A:$AK,22,FALSE())/12,0) | E13: 291696 | F13: 322783 | G13: =F13-E13 | H13: 247640 | I13: 276531
... A481: PRJ040 | B481: Dec | C481: =IFERROR(VLOOKUP(A481,Projects!$A:$AK,21,FALSE())/12,0) | D481: =IFERROR(VLOOKUP(A481,Projects!$A:$AK,22,FALSE())/12,0) | E481: 175890 | F481: 175479 | G481: =F481-E481 | H481: 157845 | I481: 150862

Sheet Resources
A1: Resource | B1: Skill | C1: Role | D1: Project ID | E1: Project | F1: Month | G1: Allocation % | H1: Capacity %
A2: Resource 01 | B2: BA | C2: Analyst | D2: PRJ022 | E2: DevOps Tools | F2: 45748 | G2: 25 | H2: 100
A3: Resource 01 | B3: BA | C3: Analyst | D3: PRJ022 | E3: DevOps Tools | F3: 45778 | G3: 25 | H3: 100
A4: Resource 01 | B4: BA | C4: Analyst | D4: PRJ022 | E4: DevOps Tools | F4: 45809 | G4: 25 | H4: 100
A5: Resource 01 | B5: BA | C5: Analyst | D5: PRJ022 | E5: DevOps Tools | F5: 45839 | G5: 40 | H5: 100
A6: Resource 01 | B6: BA | C6: Analyst | D6: PRJ022 | E6: DevOps Tools | F6: 45870 | G6: 35 | H6: 100
A7: Resource 01 | B7: BA | C7: Analyst | D7: PRJ022 | E7: DevOps Tools | F7: 45901 | G7: 35 | H7: 100
A8: Resource 01 | B8: BA | C8: Analyst | D8: PRJ022 | E8: DevOps Tools | F8: 45931 | G8: 35 | H8: 100
A9: Resource 01 | B9: BA | C9: Analyst | D9: PRJ022 | E9: DevOps Tools | F9: 45962 | G9: 15 | H9: 100
A10: Resource 01 | B10: BA | C10: Analyst | D10: PRJ022 | E10: DevOps Tools | F10: 45992 | G10: 40 | H10: 100
A11: Resource 01 | B11: BA | C11: Analyst | D11: PRJ022 | E11: DevOps Tools | F11: 46023 | G11: 0 | H11: 100
A12: Resource 01 | B12: BA | C12: Analyst | D12: PRJ040 | E12: Zero-Trust Net | F12: 45689 | G12: 90 | H12: 100
A13: Resource 01 | B13: BA | C13: Analyst | D13: PRJ040 | E13: Zero-Trust Net | F13: 45717 | G13: 50 | H13: 100
... A768: Resource 30 | B768: Data | C768: Analyst | D768: PRJ021 | E768: Data Warehouse | F768: 45809 | G768: 100 | H768: 100

Sheet Dependencies
A1: From Project | B1: To Project | C1: Dependency Type | D1: Status | E1: Impact
A2: PRJ027 | B2: PRJ022 | C2: Shared Resource | D2: Healthy | E2: Low
A3: PRJ017 | B3: PRJ033 | C3: Finish-Start | D3: At Risk | E3: Medium
A4: PRJ039 | B4: PRJ036 | C4: Blocks | D4: At Risk | E4: High
A5: PRJ002 | B5: PRJ004 | C5: Start-Start | D5: Blocked | E5: Medium
A6: PRJ009 | B6: PRJ001 | C6: Shared Resource | D6: Healthy | E6: High
A7: PRJ020 | B7: PRJ021 | C7: Finish-Start | D7: Healthy | E7: Low
A8: PRJ016 | B8: PRJ034 | C8: Start-Start | D8: Blocked | E8: High
A9: PRJ027 | B9: PRJ021 | C9: Shared Resource | D9: At Risk | E9: High
A10: PRJ009 | B10: PRJ017 | C10: Start-Start | D10: Blocked | E10: High
A11: PRJ021 | B11: PRJ019 | C11: Start-Start | D11: Healthy | E11: Medium
A12: PRJ024 | B12: PRJ012 | C12: Shared Resource | D12: At Risk | E12: High
... A41: PRJ011 | B41: PRJ030 | C41: Shared Resource | D41: Healthy | E41: Medium

Sheet Pipeline
A1: Idea ID | B1: Name | C1: Submitter | D1: Strategic Fit (1-5) | E1: Value (1-5) | F1: Risk (1-5) | G1: Effort (1-5) | H1: Priority Score | I1: Decision | J1: Est. Budget ($K)
A2: IDEA008 | B2: Quantum Pilot | C2: Priya Patel | D2: 4 | E2: 4 | F2: 3 | G2: 5 | H2: =(D2*0.3+E2*0.4-F2*0.15-G2*0.15)*20 | I2: New | J2: 724
A3: IDEA004 | B3: Edge Analytics | C3: Alex Brown | D3: 5 | E3: 2 | F3: 5 | G3: 1 | H3: =(D3*0.3+E3*0.4-F3*0.15-G3*0.15)*20 | I3: Parked | J3: 419
A4: IDEA009 | B4: SaaS Rationalisation | C4: Priya Patel | D4: 1 | E4: 5 | F4: 4 | G4: 3 | H4: =(D4*0.3+E4*0.4-F4*0.15-G4*0.15)*20 | I4: Parked | J4: 314
A5: IDEA007 | B5: Citizen Dev Studio | C5: John Smith | D5: 1 | E5: 3 | F5: 2 | G5: 1 | H5: =(D5*0.3+E5*0.4-F5*0.15-G5*0.15)*20 | I5: Rejected | J5: 1751
A6: IDEA005 | B6: Green IT | C6: Priya Patel | D6: 4 | E6: 1 | F6: 2 | G6: 4 | H6: =(D6*0.3+E6*0.4-F6*0.15-G6*0.15)*20 | I6: New | J6: 1867
A7: IDEA001 | B7: Process Automation v2 | C7: Sarah Lee | D7: 1 | E7: 4 | F7: 3 | G7: 5 | H7: =(D7*0.3+E7*0.4-F7*0.15-G7*0.15)*20 | I7: Rejected | J7: 1059
A8: IDEA006 | B8: ESG Data Hub | C8: Sarah Lee | D8: 3 | E8: 1 | F8: 3 | G8: 1 | H8: =(D8*0.3+E8*0.4-F8*0.15-G8*0.15)*20 | I8: Approved | J8: 1259
A9: IDEA003 | B9: ML Ops Platform | C9: Carlos Diaz | D9: 3 | E9: 2 | F9: 2 | G9: 5 | H9: =(D9*0.3+E9*0.4-F9*0.15-G9*0.15)*20 | I9: Approved | J9: 1203
A10: IDEA002 | B10: Customer 360 | C10: John Smith | D10: 1 | E10: 2 | F10: 1 | G10: 3 | H10: =(D10*0.3+E10*0.4-F10*0.15-G10*0.15)*20 | I10: Under Review | J10: 1828
A11: IDEA010 | B11: Zero Trust v2 | C11: Carlos Diaz | D11: 2 | E11: 1 | F11: 3 | G11: 3 | H11: =(D11*0.3+E11*0.4-F11*0.15-G11*0.15)*20 | I11: New | J11: 1573

Sheet CostBenefit
A1: Project ID | B1: Project Name | C1: Program | D1: Year Offset | E1: Year | F1: CAPEX | G1: OPEX | H1: Total Cost | I1: Benefit Recurring | J1: Benefit One-Off | K1: Total Benefit | L1: Net Benefit | M1: Benefit Type | N1: Benefit Category | O1: Confidence %
A2: PRJ001 | B2: =IFERROR(VLOOKUP(A2,Projects!$A:$AK,2,FALSE()),"") | C2: =IFERROR(VLOOKUP(A2,Projects!$A:$AK,3,FALSE()),"") | D2: 0 | E2: =IFERROR(YEAR(VLOOKUP(A2,Projects!$A:$AK,16,FALSE()))+D2,D2) | F2: =IFERROR(VLOOKUP(A2,Projects!$A:$AK,21,FALSE()),"") | G2: =IFERROR(VLOOKUP(A2,Projects!$A:$AK,22,FALSE()),"") | H2: =F2+G2 | I2: 0 | J2: 0 | K2: =I2+J2 | L2: =K2-H2 | M2: Recurring | N2: Compliance | O2: 70
A3: PRJ001 | B3: =IFERROR(VLOOKUP(A3,Projects!$A:$AK,2,FALSE()),"") | C3: =IFERROR(VLOOKUP(A3,Projects!$A:$AK,3,FALSE()),"") | D3: 1 | E3: =IFERROR(YEAR(VLOOKUP(A3,Projects!$A:$AK,16,FALSE()))+D3,D3) | F3: =IFERROR(VLOOKUP(A3,Projects!$A:$AK,21,FALSE()),"") | G3: =IFERROR(VLOOKUP(A3,Projects!$A:$AK,22,FALSE()),"") | H3: =F3+G3 | I3: 738473 | J3: 0 | K3: =I3+J3 | L3: =K3-H3 | M3: Recurring | N3: Compliance | O3: 70
A4: PRJ001 | B4: =IFERROR(VLOOKUP(A4,Projects!$A:$AK,2,FALSE()),"") | C4: =IFERROR(VLOOKUP(A4,Projects!$A:$AK,3,FALSE()),"") | D4: 2 | E4: =IFERROR(YEAR(VLOOKUP(A4,Projects!$A:$AK,16,FALSE()))+D4,D4) | F4: =IFERROR(VLOOKUP(A4,Projects!$A:$AK,21,FALSE()),"") | G4: =IFERROR(VLOOKUP(A4,Projects!$A:$AK,22,FALSE()),"") | H4: =F4+G4 | I4: 807665 | J4: 0 | K4: =I4+J4 | L4: =K4-H4 | M4: Recurring | N4: Compliance | O4: 70
A5: PRJ001 | B5: =IFERROR(VLOOKUP(A5,Projects!$A:$AK,2,FALSE()),"") | C5: =IFERROR(VLOOKUP(A5,Projects!$A:$AK,3,FALSE()),"") | D5: 3 | E5: =IFERROR(YEAR(VLOOKUP(A5,Projects!$A:$AK,16,FALSE()))+D5,D5) | F5: =IFERROR(VLOOKUP(A5,Projects!$A:$AK,21,FALSE()),"") | G5: =IFERROR(VLOOKUP(A5,Projects!$A:$AK,22,FALSE()),"") | H5: =F5+G5 | I5: 859774 | J5: 0 | K5: =I5+J5 | L5: =K5-H5 | M5: Recurring | N5: Compliance | O5: 80
A6: PRJ001 | B6: =IFERROR(VLOOKUP(A6,Projects!$A:$AK,2,FALSE()),"") | C6: =IFERROR(VLOOKUP(A6,Projects!$A:$AK,3,FALSE()),"") | D6: 4 | E6: =IFERROR(YEAR(VLOOKUP(A6,Projects!$A:$AK,16,FALSE()))+D6,D6) | F6: =IFERROR(VLOOKUP(A6,Projects!$A:$AK,21,FALSE()),"") | G6: =IFERROR(VLOOKUP(A6,Projects!$A:$AK,22,FALSE()),"") | H6: =F6+G6 | I6: 833860 | J6: 0 | K6: =I6+J6 | L6: =K6-H6 | M6: Recurring | N6: Compliance | O6: 60
A7: PRJ002 | B7: =IFERROR(VLOOKUP(A7,Projects!$A:$AK,2,FALSE()),"") | C7: =IFERROR(VLOOKUP(A7,Projects!$A:$AK,3,FALSE()),"") | D7: 0 | E7: =IFERROR(YEAR(VLOOKUP(A7,Projects!$A:$AK,16,FALSE()))+D7,D7) | F7: =IFERROR(VLOOKUP(A7,Projects!$A:$AK,21,FALSE()),"") | G7: =IFERROR(VLOOKUP(A7,Projects!$A:$AK,22,FALSE()),"") | H7: =F7+G7 | I7: 0 | J7: 0 | K7: =I7+J7 | L7: =K7-H7 | M7: Recurring | N7: Compliance | O7: 90
A8: PRJ002 | B8: =IFERROR(VLOOKUP(A8,Projects!$A:$AK,2,FALSE()),"") | C8: =IFERROR(VLOOKUP(A8,Projects!$A:$AK,3,FALSE()),"") | D8: 1 | E8: =IFERROR(YEAR(VLOOKUP(A8,Projects!$A:$AK,16,FALSE()))+D8,D8) | F8: =IFERROR(VLOOKUP(A8,Projects!$A:$AK,21,FALSE()),"") | G8: =IFERROR(VLOOKUP(A8,Projects!$A:$AK,22,FALSE()),"") | H8: =F8+G8 | I8: 653868 | J8: 0 | K8: =I8+J8 | L8: =K8-H8 | M8: Recurring | N8: Compliance | O8: 70
A9: PRJ002 | B9: =IFERROR(VLOOKUP(A9,Projects!$A:$AK,2,FALSE()),"") | C9: =IFERROR(VLOOKUP(A9,Projects!$A:$AK,3,FALSE()),"") | D9: 2 | E9: =IFERROR(YEAR(VLOOKUP(A9,Projects!$A:$AK,16,FALSE()))+D9,D9) | F9: =IFERROR(VLOOKUP(A9,Projects!$A:$AK,21,FALSE()),"") | G9: =IFERROR(VLOOKUP(A9,Projects!$A:$AK,22,FALSE()),"") | H9: =F9+G9 | I9: 563363 | J9: 0 | K9: =I9+J9 | L9: =K9-H9 | M9: Recurring | N9: Compliance | O9: 80
A10: PRJ002 | B10: =IFERROR(VLOOKUP(A10,Projects!$A:$AK,2,FALSE()),"") | C10: =IFERROR(VLOOKUP(A10,Projects!$A:$AK,3,FALSE()),"") | D10: 3 | E10: =IFERROR(YEAR(VLOOKUP(A10,Projects!$A:$AK,16,FALSE()))+D10,D10) | F10: =IFERROR(VLOOKUP(A10,Projects!$A:$AK,21,FALSE()),"") | G10: =IFERROR(VLOOKUP(A10,Projects!$A:$AK,22,FALSE()),"") | H10: =F10+G10 | I10: 731003 | J10: 0 | K10: =I10+J10 | L10: =K10-H10 | M10: Recurring | N10: Compliance | O10: 70
A11: PRJ002 | B11: =IFERROR(VLOOKUP(A11,Projects!$A:$AK,2,FALSE()),"") | C11: =IFERROR(VLOOKUP(A11,Projects!$A:$AK,3,FALSE()),"") | D11: 4 | E11: =IFERROR(YEAR(VLOOKUP(A11,Projects!$A:$AK,16,FALSE()))+D11,D11) | F11: =IFERROR(VLOOKUP(A11,Projects!$A:$AK,21,FALSE()),"") | G11: =IFERROR(VLOOKUP(A11,Projects!$A:$AK,22,FALSE()),"") | H11: =F11+G11 | I11: 730897 | J11: 0 | K11: =I11+J11 | L11: =K11-H11 | M11: Recurring | N11: Compliance | O11: 60
A12: PRJ003 | B12: =IFERROR(VLOOKUP(A12,Projects!$A:$AK,2,FALSE()),"") | C12: =IFERROR(VLOOKUP(A12,Projects!$A:$AK,3,FALSE()),"") | D12: 0 | E12: =IFERROR(YEAR(VLOOKUP(A12,Projects!$A:$AK,16,FALSE()))+D12,D12) | F12: =IFERROR(VLOOKUP(A12,Projects!$A:$AK,21,FALSE()),"") | G12: =IFERROR(VLOOKUP(A12,Projects!$A:$AK,22,FALSE()),"") | H12: =F12+G12 | I12: 0 | J12: 0 | K12: =I12+J12 | L12: =K12-H12 | M12: Recurring | N12: Risk Avoidance | O12: 70
A13: PRJ003 | B13: =IFERROR(VLOOKUP(A13,Projects!$A:$AK,2,FALSE()),"") | C13: =IFERROR(VLOOKUP(A13,Projects!$A:$AK,3,FALSE()),"") | D13: 1 | E13: =IFERROR(YEAR(VLOOKUP(A13,Projects!$A:$AK,16,FALSE()))+D13,D13) | F13: =IFERROR(VLOOKUP(A13,Projects!$A:$AK,21,FALSE()),"") | G13: =IFERROR(VLOOKUP(A13,Projects!$A:$AK,22,FALSE()),"") | H13: =F13+G13 | I13: 2114749 | J13: 0 | K13: =I13+J13 | L13: =K13-H13 | M13: Recurring | N13: Risk Avoidance | O13: 90
... A201: PRJ040 | B201: =IFERROR(VLOOKUP(A201,Projects!$A:$AK,2,FALSE()),"") | C201: =IFERROR(VLOOKUP(A201,Projects!$A:$AK,3,FALSE()),"") | D201: 4 | E201: =IFERROR(YEAR(VLOOKUP(A201,Projects!$A:$AK,16,FALSE()))+D201,D201) | F201: =IFERROR(VLOOKUP(A201,Projects!$A:$AK,21,FALSE()),"") | G201: =IFERROR(VLOOKUP(A201,Projects!$A:$AK,22,FALSE()),"") | H201: =F201+G201 | I201: 0 | J201: 0 | K201: =I201+J201 | L201: =K201-H201 | M201: One-Off | N201: Compliance | O201: 70

Sheet Benefits
A1: Benefit ID | B1: Project ID | C1: Project Name | D1: Description | E1: Category | F1: Target Value | G1: Realised Value | H1: Benefits Remaining | I1: Realisation % | J1: Owner | K1: Start Date | L1: End Date | M1: Status
A2: BEN001 | B2: PRJ001 | C2: =IFERROR(VLOOKUP(B2,Projects!$A:$AK,2,FALSE()),"") | D2: Process cycle-time reduction | E2: Cost Reduction | F2: 569626 | G2: 250989 | H2: =F2-G2 | I2: =IFERROR(G2/F2,0) | J2: Carlos Diaz | K2: =IFERROR(VLOOKUP(B2,Projects!$A:$AK,16,FALSE()),"") | L2: =IFERROR(VLOOKUP(B2,Projects!$A:$AK,17,FALSE()),"") | M2: At Risk
A3: BEN002 | B3: PRJ001 | C3: =IFERROR(VLOOKUP(B3,Projects!$A:$AK,2,FALSE()),"") | D3: Risk loss avoidance | E3: Compliance | F3: 497551 | G3: 28353 | H3: =F3-G3 | I3: =IFERROR(G3/F3,0) | J3: Alex Brown | K3: =IFERROR(VLOOKUP(B3,Projects!$A:$AK,16,FALSE()),"") | L3: =IFERROR(VLOOKUP(B3,Projects!$A:$AK,17,FALSE()),"") | M3: At Risk
A4: BEN003 | B4: PRJ002 | C4: =IFERROR(VLOOKUP(B4,Projects!$A:$AK,2,FALSE()),"") | D4: Regulatory compliance achievement | E4: Customer Experience | F4: 1527159 | G4: 400095 | H4: =F4-G4 | I4: =IFERROR(G4/F4,0) | J4: Jane Doe | K4: =IFERROR(VLOOKUP(B4,Projects!$A:$AK,16,FALSE()),"") | L4: =IFERROR(VLOOKUP(B4,Projects!$A:$AK,17,FALSE()),"") | M4: Realised
A5: BEN004 | B5: PRJ002 | C5: =IFERROR(VLOOKUP(B5,Projects!$A:$AK,2,FALSE()),"") | D5: Risk loss avoidance | E5: Customer Experience | F5: 1098404 | G5: 371599 | H5: =F5-G5 | I5: =IFERROR(G5/F5,0) | J5: Mike Johnson | K5: =IFERROR(VLOOKUP(B5,Projects!$A:$AK,16,FALSE()),"") | L5: =IFERROR(VLOOKUP(B5,Projects!$A:$AK,17,FALSE()),"") | M5: Planned
A6: BEN005 | B6: PRJ002 | C6: =IFERROR(VLOOKUP(B6,Projects!$A:$AK,2,FALSE()),"") | D6: Risk loss avoidance | E6: Cost Reduction | F6: 493679 | G6: 309250 | H6: =F6-G6 | I6: =IFERROR(G6/F6,0) | J6: Sarah Lee | K6: =IFERROR(VLOOKUP(B6,Projects!$A:$AK,16,FALSE()),"") | L6: =IFERROR(VLOOKUP(B6,Projects!$A:$AK,17,FALSE()),"") | M6: At Risk
A7: BEN006 | B7: PRJ003 | C7: =IFERROR(VLOOKUP(B7,Projects!$A:$AK,2,FALSE()),"") | D7: Process cycle-time reduction | E7: Productivity Improvement | F7: 1185604 | G7: 776392 | H7: =F7-G7 | I7: =IFERROR(G7/F7,0) | J7: Alex Brown | K7: =IFERROR(VLOOKUP(B7,Projects!$A:$AK,16,FALSE()),"") | L7: =IFERROR(VLOOKUP(B7,Projects!$A:$AK,17,FALSE()),"") | M7: Planned
A8: BEN007 | B8: PRJ003 | C8: =IFERROR(VLOOKUP(B8,Projects!$A:$AK,2,FALSE()),"") | D8: Revenue growth from new channel | E8: Risk Reduction | F8: 660591 | G8: 239910 | H8: =F8-G8 | I8: =IFERROR(G8/F8,0) | J8: John Smith | K8: =IFERROR(VLOOKUP(B8,Projects!$A:$AK,16,FALSE()),"") | L8: =IFERROR(VLOOKUP(B8,Projects!$A:$AK,17,FALSE()),"") | M8: Realised
A9: BEN008 | B9: PRJ004 | C9: =IFERROR(VLOOKUP(B9,Projects!$A:$AK,2,FALSE()),"") | D9: Process cycle-time reduction | E9: Customer Experience | F9: 957187 | G9: 289792 | H9: =F9-G9 | I9: =IFERROR(G9/F9,0) | J9: Mike Johnson | K9: =IFERROR(VLOOKUP(B9,Projects!$A:$AK,16,FALSE()),"") | L9: =IFERROR(VLOOKUP(B9,Projects!$A:$AK,17,FALSE()),"") | M9: Planned
A10: BEN009 | B10: PRJ004 | C10: =IFERROR(VLOOKUP(B10,Projects!$A:$AK,2,FALSE()),"") | D10: Customer NPS uplift | E10: Revenue Increase | F10: 441175 | G10: 72200 | H10: =F10-G10 | I10: =IFERROR(G10/F10,0) | J10: Mike Johnson | K10: =IFERROR(VLOOKUP(B10,Projects!$A:$AK,16,FALSE()),"") | L10: =IFERROR(VLOOKUP(B10,Projects!$A:$AK,17,FALSE()),"") | M10: Planned
A11: BEN010 | B11: PRJ005 | C11: =IFERROR(VLOOKUP(B11,Projects!$A:$AK,2,FALSE()),"") | D11: Headcount cost avoidance | E11: Productivity Improvement | F11: 1860551 | G11: 128167 | H11: =F11-G11 | I11: =IFERROR(G11/F11,0) | J11: John Smith | K11: =IFERROR(VLOOKUP(B11,Projects!$A:$AK,16,FALSE()),"") | L11: =IFERROR(VLOOKUP(B11,Projects!$A:$AK,17,FALSE()),"") | M11: Realised
A12: BEN011 | B12: PRJ005 | C12: =IFERROR(VLOOKUP(B12,Projects!$A:$AK,2,FALSE()),"") | D12: Process cycle-time reduction | E12: Compliance | F12: 473628 | G12: 109157 | H12: =F12-G12 | I12: =IFERROR(G12/F12,0) | J12: Carlos Diaz | K12: =IFERROR(VLOOKUP(B12,Projects!$A:$AK,16,FALSE()),"") | L12: =IFERROR(VLOOKUP(B12,Projects!$A:$AK,17,FALSE()),"") | M12: In Progress
A13: BEN012 | B13: PRJ006 | C13: =IFERROR(VLOOKUP(B13,Projects!$A:$AK,2,FALSE()),"") | D13: Customer NPS uplift | E13: Compliance | F13: 1247665 | G13: 120407 | H13: =F13-G13 | I13: =IFERROR(G13/F13,0) | J13: Alex Brown | K13: =IFERROR(VLOOKUP(B13,Projects!$A:$AK,16,FALSE()),"") | L13: =IFERROR(VLOOKUP(B13,Projects!$A:$AK,17,FALSE()),"") | M13: Realised
... A81: BEN080 | B81: PRJ040 | C81: =IFERROR(VLOOKUP(B81,Projects!$A:$AK,2,FALSE()),"") | D81: Process cycle-time reduction | E81: Revenue Increase | F81: 656939 | G81: 173701 | H81: =F81-G81 | I81: =IFERROR(G81/F81,0) | J81: Mike Johnson | K81: =IFERROR(VLOOKUP(B81,Projects!$A:$AK,16,FALSE()),"") | L81: =IFERROR(VLOOKUP(B81,Projects!$A:$AK,17,FALSE()),"") | M81: In Progress

Sheet Decisions
A1: Decision ID | B1: Type | C1: Project ID | D1: Program | E1: Description | F1: Required By | G1: Owner | H1: Due Date | I1: Priority | J1: Status | K1: Outcome | L1: Approval Date
A2: DEC001 | B2: General | D2: =IFERROR(VLOOKUP(C2,Projects!$A:$AK,3,FALSE()),"") | E2: Approve full project funding | F2: CIO | G2: Mike Johnson | H2: 46146 | I2: =IFERROR(VLOOKUP(C2,Projects!$A:$AK,10,FALSE()),"") | J2: Closed
A3: DEC002 | B3: Project | C3: PRJ007 | D3: =IFERROR(VLOOKUP(C3,Projects!$A:$AK,3,FALSE()),"") | E3: Approve architecture pattern | F3: CIO | G3: Sarah Lee | H3: 46226 | I3: =IFERROR(VLOOKUP(C3,Projects!$A:$AK,10,FALSE()),"") | J3: Closed
A4: DEC003 | B4: SteerCo | C4: PRJ032 | D4: =IFERROR(VLOOKUP(C4,Projects!$A:$AK,3,FALSE()),"") | E4: Defer benefits realisation date | F4: COO | G4: Alex Brown | H4: 46218 | I4: =IFERROR(VLOOKUP(C4,Projects!$A:$AK,10,FALSE()),"") | J4: Approved
A5: DEC004 | B5: Architecture | C5: PRJ021 | D5: =IFERROR(VLOOKUP(C5,Projects!$A:$AK,3,FALSE()),"") | E5: Cut scope of MVP | F5: CMO | G5: Sarah Lee | H5: 46118 | I5: =IFERROR(VLOOKUP(C5,Projects!$A:$AK,10,FALSE()),"") | J5: Open
A6: DEC005 | B6: Architecture | C6: PRJ007 | D6: =IFERROR(VLOOKUP(C6,Projects!$A:$AK,3,FALSE()),"") | E6: Re-baseline schedule | F6: CMO | G6: Priya Patel | H6: 46115 | I6: =IFERROR(VLOOKUP(C6,Projects!$A:$AK,10,FALSE()),"") | J6: Open
A7: DEC006 | B7: Program | C7: PRJ034 | D7: =IFERROR(VLOOKUP(C7,Projects!$A:$AK,3,FALSE()),"") | E7: Accept residual risk | F7: CFO | G7: Mike Johnson | H7: 46178 | I7: =IFERROR(VLOOKUP(C7,Projects!$A:$AK,10,FALSE()),"") | J7: Closed
A8: DEC007 | B8: General | C8: PRJ033 | D8: =IFERROR(VLOOKUP(C8,Projects!$A:$AK,3,FALSE()),"") | E8: Accept residual risk | F8: CFO | G8: John Smith | H8: 46199 | I8: =IFERROR(VLOOKUP(C8,Projects!$A:$AK,10,FALSE()),"") | J8: Approved
A9: DEC008 | B9: Architecture | C9: PRJ003 | D9: =IFERROR(VLOOKUP(C9,Projects!$A:$AK,3,FALSE()),"") | E9: Accept residual risk | F9: CMO | G9: Jane Doe | H9: 46028 | I9: =IFERROR(VLOOKUP(C9,Projects!$A:$AK,10,FALSE()),"") | J9: Rejected
A10: DEC009 | B10: Program | C10: PRJ023 | D10: =IFERROR(VLOOKUP(C10,Projects!$A:$AK,3,FALSE()),"") | E10: Re-baseline schedule | F10: CIO | G10: Priya Patel | H10: 46126 | I10: =IFERROR(VLOOKUP(C10,Projects!$A:$AK,10,FALSE()),"") | J10: Approved
A11: DEC010 | B11: Funding | C11: PRJ010 | D11: =IFERROR(VLOOKUP(C11,Projects!$A:$AK,3,FALSE()),"") | E11: Choose vendor for cloud migration | F11: CMO | G11: Carlos Diaz | H11: 46179 | I11: =IFERROR(VLOOKUP(C11,Projects!$A:$AK,10,FALSE()),"") | J11: Approved
A12: DEC011 | B12: General | C12: PRJ011 | D12: =IFERROR(VLOOKUP(C12,Projects!$A:$AK,3,FALSE()),"") | E12: Approve full project funding | F12: CMO | G12: Priya Patel | H12: 46237 | I12: =IFERROR(VLOOKUP(C12,Projects!$A:$AK,10,FALSE()),"") | J12: In Review
A13: DEC012 | B13: Funding | C13: PRJ011 | D13: =IFERROR(VLOOKUP(C13,Projects!$A:$AK,3,FALSE()),"") | E13: Approve full project funding | F13: CMO | G13: Priya Patel | H13: 46086 | I13: =IFERROR(VLOOKUP(C13,Projects!$A:$AK,10,FALSE()),"") | J13: In Review
A14: DEC013 | B14: Risk | C14: PRJ018 | D14: =IFERROR(VLOOKUP(C14,Projects!$A:$AK,3,FALSE()),"") | E14: Accept residual risk | F14: COO | G14: Priya Patel | H14: 46107 | I14: =IFERROR(VLOOKUP(C14,Projects!$A:$AK,10,FALSE()),"") | J14: Open
A15: DEC014 | B15: Portfolio | C15: PRJ035 | D15: =IFERROR(VLOOKUP(C15,Projects!$A:$AK,3,FALSE()),"") | E15: Approve full project funding | F15: COO | G15: Carlos Diaz | H15: 46194 | I15: =IFERROR(VLOOKUP(C15,Projects!$A:$AK,10,FALSE()),"") | J15: Closed
A16: DEC015 | B16: Program | D16: =IFERROR(VLOOKUP(C16,Projects!$A:$AK,3,FALSE()),"") | E16: Re-baseline schedule | F16: CMO | G16: Priya Patel | H16: 46220 | I16: =IFERROR(VLOOKUP(C16,Projects!$A:$AK,10,FALSE()),"") | J16: Closed
A17: DEC016 | B17: Risk | C17: PRJ015 | D17: =IFERROR(VLOOKUP(C17,Projects!$A:$AK,3,FALSE()),"") | E17: Cut scope of MVP | F17: CIO | G17: Mike Johnson | H17: 46243 | I17: =IFERROR(VLOOKUP(C17,Projects!$A:$AK,10,FALSE()),"") | J17: Open
A18: DEC017 | B18: Architecture | C18: PRJ038 | D18: =IFERROR(VLOOKUP(C18,Projects!$A:$AK,3,FALSE()),"") | E18: Accept residual risk | F18: CIO | G18: Alex Brown | H18: 46046 | I18: =IFERROR(VLOOKUP(C18,Projects!$A:$AK,10,FALSE()),"") | J18: In Review
A19: DEC018 | B19: Architecture | C19: PRJ025 | D19: =IFERROR(VLOOKUP(C19,Projects!$A:$AK,3,FALSE()),"") | E19: Cut scope of MVP | F19: CIO | G19: Alex Brown | H19: 46242 | I19: =IFERROR(VLOOKUP(C19,Projects!$A:$AK,10,FALSE()),"") | J19: In Review
A20: DEC019 | B20: Risk | C20: PRJ028 | D20: =IFERROR(VLOOKUP(C20,Projects!$A:$AK,3,FALSE()),"") | E20: Defer benefits realisation date | F20: COO | G20: Carlos Diaz | H20: 46240 | I20: =IFERROR(VLOOKUP(C20,Projects!$A:$AK,10,FALSE()),"") | J20: In Review
A21: DEC020 | B21: Funding | C21: PRJ007 | D21: =IFERROR(VLOOKUP(C21,Projects!$A:$AK,3,FALSE()),"") | E21: Approve full project funding | F21: CTO | G21: Carlos Diaz | H21: 46157 | I21: =IFERROR(VLOOKUP(C21,Projects!$A:$AK,10,FALSE()),"") | J21: Approved
A22: DEC021 | B22: SteerCo | C22: PRJ015 | D22: =IFERROR(VLOOKUP(C22,Projects!$A:$AK,3,FALSE()),"") | E22: Accept residual risk | F22: CMO | G22: Jane Doe | H22: 46061 | I22: =IFERROR(VLOOKUP(C22,Projects!$A:$AK,10,FALSE()),"") | J22: Approved
A23: DEC022 | B23: Project | C23: PRJ039 | D23: =IFERROR(VLOOKUP(C23,Projects!$A:$AK,3,FALSE()),"") | E23: Cut scope of MVP | F23: CTO | G23: Priya Patel | H23: 46061 | I23: =IFERROR(VLOOKUP(C23,Projects!$A:$AK,10,FALSE()),"") | J23: Approved
A24: DEC023 | B24: General | D24: =IFERROR(VLOOKUP(C24,Projects!$A:$AK,3,FALSE()),"") | E24: Re-baseline schedule | F24: COO | G24: Priya Patel | H24: 46241 | I24: =IFERROR(VLOOKUP(C24,Projects!$A:$AK,10,FALSE()),"") | J24: Open
A25: DEC024 | B25: Architecture | C25: PRJ010 | D25: =IFERROR(VLOOKUP(C25,Projects!$A:$AK,3,FALSE()),"") | E25: Defer benefits realisation date | F25: CFO | G25: Priya Patel | H25: 46231 | I25: =IFERROR(VLOOKUP(C25,Projects!$A:$AK,10,FALSE()),"") | J25: Open
A26: DEC025 | B26: Portfolio | C26: PRJ032 | D26: =IFERROR(VLOOKUP(C26,Projects!$A:$AK,3,FALSE()),"") | E26: Cut scope of MVP | F26: CFO | G26: John Smith | H26: 46245 | I26: =IFERROR(VLOOKUP(C26,Projects!$A:$AK,10,FALSE()),"") | J26: Rejected
A27: DEC026 | B27: Risk | D27: =IFERROR(VLOOKUP(C27,Projects!$A:$AK,3,FALSE()),"") | E27: Cut scope of MVP | F27: CMO | G27: Sarah Lee | H27: 46110 | I27: =IFERROR(VLOOKUP(C27,Projects!$A:$AK,10,FALSE()),"") | J27: Closed
A28: DEC027 | B28: SteerCo | C28: PRJ019 | D28: =IFERROR(VLOOKUP(C28,Projects!$A:$AK,3,FALSE()),"") | E28: Accept residual risk | F28: CTO | G28: Sarah Lee | H28: 46210 | I28: =IFERROR(VLOOKUP(C28,Projects!$A:$AK,10,FALSE()),"") | J28: In Review
A29: DEC028 | B29: Project | C29: PRJ020 | D29: =IFERROR(VLOOKUP(C29,Projects!$A:$AK,3,FALSE()),"") | E29: Accept residual risk | F29: CFO | G29: Alex Brown | H29: 46106 | I29: =IFERROR(VLOOKUP(C29,Projects!$A:$AK,10,FALSE()),"") | J29: Rejected
A30: DEC029 | B30: General | C30: PRJ019 | D30: =IFERROR(VLOOKUP(C30,Projects!$A:$AK,3,FALSE()),"") | E30: Choose vendor for cloud migration | F30: CFO | G30: Carlos Diaz | H30: 46202 | I30: =IFERROR(VLOOKUP(C30,Projects!$A:$AK,10,FALSE()),"") | J30: In Review
A31: DEC030 | B31: Project | C31: PRJ024 | D31: =IFERROR(VLOOKUP(C31,Projects!$A:$AK,3,FALSE()),"") | E31: Accept residual risk | F31: CFO | G31: Sarah Lee | H31: 46212 | I31: =IFERROR(VLOOKUP(C31,Projects!$A:$AK,10,FALSE()),"") | J31: In Review
A32: DEC031 | B32: Program | C32: PRJ023 | D32: =IFERROR(VLOOKUP(C32,Projects!$A:$AK,3,FALSE()),"") | E32: Choose vendor for cloud migration | F32: CIO | G32: John Smith | H32: 46038 | I32: =IFERROR(VLOOKUP(C32,Projects!$A:$AK,10,FALSE()),"") | J32: Approved
A33: DEC032 | B33: Risk | C33: PRJ010 | D33: =IFERROR(VLOOKUP(C33,Projects!$A:$AK,3,FALSE()),"") | E33: Choose vendor for cloud migration | F33: CIO | G33: John Smith | H33: 46175 | I33: =IFERROR(VLOOKUP(C33,Projects!$A:$AK,10,FALSE()),"") | J33: Rejected
A34: DEC033 | B34: SteerCo | C34: PRJ039 | D34: =IFERROR(VLOOKUP(C34,Projects!$A:$AK,3,FALSE()),"") | E34: Accept residual risk | F34: CMO | G34: Carlos Diaz | H34: 46149 | I34: =IFERROR(VLOOKUP(C34,Projects!$A:$AK,10,FALSE()),"") | J34: Open
A35: DEC034 | B35: General | D35: =IFERROR(VLOOKUP(C35,Projects!$A:$AK,3,FALSE()),"") | E35: Cut scope of MVP | F35: CMO | G35: Mike Johnson | H35: 46223 | I35: =IFERROR(VLOOKUP(C35,Projects!$A:$AK,10,FALSE()),"") | J35: Open
A36: DEC035 | B36: Program | C36: PRJ008 | D36: =IFERROR(VLOOKUP(C36,Projects!$A:$AK,3,FALSE()),"") | E36: Accept residual risk | F36: CTO | G36: Jane Doe | H36: 46053 | I36: =IFERROR(VLOOKUP(C36,Projects!$A:$AK,10,FALSE()),"") | J36: Closed
A37: DEC036 | B37: General | C37: PRJ018 | D37: =IFERROR(VLOOKUP(C37,Projects!$A:$AK,3,FALSE()),"") | E37: Defer benefits realisation date | F37: CTO | G37: Jane Doe | H37: 46170 | I37: =IFERROR(VLOOKUP(C37,Projects!$A:$AK,10,FALSE()),"") | J37: Rejected
A38: DEC037 | B38: Risk | C38: PRJ020 | D38: =IFERROR(VLOOKUP(C38,Projects!$A:$AK,3,FALSE()),"") | E38: Approve full project funding | F38: COO | G38: John Smith | H38: 46189 | I38: =IFERROR(VLOOKUP(C38,Projects!$A:$AK,10,FALSE()),"") | J38: Closed
A39: DEC038 | B39: Risk | C39: PRJ002 | D39: =IFERROR(VLOOKUP(C39,Projects!$A:$AK,3,FALSE()),"") | E39: Approve architecture pattern | F39: CTO | G39: Carlos Diaz | H39: 46071 | I39: =IFERROR(VLOOKUP(C39,Projects!$A:$AK,10,FALSE()),"") | J39: Rejected
A40: DEC039 | B40: Program | C40: PRJ014 | D40: =IFERROR(VLOOKUP(C40,Projects!$A:$AK,3,FALSE()),"") | E40: Choose vendor for cloud migration | F40: CTO | G40: Priya Patel | H40: 46040 | I40: =IFERROR(VLOOKUP(C40,Projects!$A:$AK,10,FALSE()),"") | J40: Open
...

Sheet Actions
A1: Action ID | B1: Project ID | C1: Description | D1: Owner | E1: Due Date | F1: Priority | G1: Status | H1: Comments
A2: ACT001 | B2: PRJ017 | C2: Close out stage gate evidence | D2: Carlos Diaz | E2: 46029 | F2: High | G2: Complete
A3: ACT002 | B3: PRJ033 | C3: Publish SteerCo pack | D3: Mike Johnson | E3: 46028 | F3: Low | G3: Overdue
A4: ACT003 | B4: PRJ001 | C4: Update risk register | D4: Mike Johnson | E4: 46050 | F4: High | G4: Overdue
A5: ACT004 | B5: PRJ035 | C5: Resolve blocker on environment | D5: Jane Doe | E5: 46139 | F5: Low | G5: Overdue
A6: ACT005 | B6: PRJ021 | C6: Schedule architecture review | D6: Mike Johnson | E6: 46132 | F6: Low | G6: Complete
A7: ACT006 | B7: PRJ014 | C7: Submit funding paper | D7: John Smith | E7: 46144 | F7: Low | G7: Complete
A8: ACT007 | B8: PRJ016 | C8: Confirm vendor SOW | D8: Jane Doe | E8: 46216 | F8: High | G8: Overdue
A9: ACT008 | B9: PRJ009 | C9: Schedule architecture review | D9: Alex Brown | E9: 46083 | F9: High | G9: Overdue
A10: ACT009 | B10: PRJ018 | C10: Update risk register | D10: Priya Patel | E10: 46158 | F10: Low | G10: Overdue
A11: ACT010 | B11: PRJ036 | C11: Publish SteerCo pack | D11: Mike Johnson | E11: 46115 | F11: Medium | G11: Overdue
A12: ACT011 | B12: PRJ026 | C12: Resolve blocker on environment | D12: John Smith | E12: 46173 | F12: Medium | G12: Overdue
A13: ACT012 | B13: PRJ010 | C13: Schedule architecture review | D13: Jane Doe | E13: 46180 | F13: High | G13: Overdue
... A61: ACT060 | B61: PRJ032 | C61: Schedule architecture review | D61: Sarah Lee | E61: 46037 | F61: Low | G61: Overdue

Sheet Milestones
A1: Project ID | B1: Milestone | C1: Planned Date | D1: Forecast Date | E1: Actual Date | F1: Status | G1: Owner | H1: Source | I1: _Key
A2: PRJ001 | B2: Discovery | C2: =IFERROR(INDEX(StageGates!$I:$I,MATCH(I2,StageGates!$O:$O,0)),"") | D2: =IFERROR(INDEX(StageGates!$J:$J,MATCH(I2,StageGates!$O:$O,0)),"") | E2: =IFERROR(INDEX(StageGates!$J:$J,MATCH(I2,StageGates!$O:$O,0)),"") | F2: =IFERROR(INDEX(StageGates!$G:$G,MATCH(I2,StageGates!$O:$O,0)),"") | G2: =IFERROR(INDEX(StageGates!$H:$H,MATCH(I2,StageGates!$O:$O,0)),"") | H2: StageGate | I2: =A2&"|"&B2
A3: PRJ001 | B3: Business Case / Seed Funding | C3: =IFERROR(INDEX(StageGates!$I:$I,MATCH(I3,StageGates!$O:$O,0)),"") | D3: =IFERROR(INDEX(StageGates!$J:$J,MATCH(I3,StageGates!$O:$O,0)),"") | E3: =IFERROR(INDEX(StageGates!$J:$J,MATCH(I3,StageGates!$O:$O,0)),"") | F3: =IFERROR(INDEX(StageGates!$G:$G,MATCH(I3,StageGates!$O:$O,0)),"") | G3: =IFERROR(INDEX(StageGates!$H:$H,MATCH(I3,StageGates!$O:$O,0)),"") | H3: StageGate | I3: =A3&"|"&B3
A4: PRJ001 | B4: Design | C4: =IFERROR(INDEX(StageGates!$I:$I,MATCH(I4,StageGates!$O:$O,0)),"") | D4: =IFERROR(INDEX(StageGates!$J:$J,MATCH(I4,StageGates!$O:$O,0)),"") | E4: =IFERROR(INDEX(StageGates!$J:$J,MATCH(I4,StageGates!$O:$O,0)),"") | F4: =IFERROR(INDEX(StageGates!$G:$G,MATCH(I4,StageGates!$O:$O,0)),"") | G4: =IFERROR(INDEX(StageGates!$H:$H,MATCH(I4,StageGates!$O:$O,0)),"") | H4: StageGate | I4: =A4&"|"&B4
A5: PRJ001 | B5: Business Case / Full Funding | C5: =IFERROR(INDEX(StageGates!$I:$I,MATCH(I5,StageGates!$O:$O,0)),"") | D5: =IFERROR(INDEX(StageGates!$J:$J,MATCH(I5,StageGates!$O:$O,0)),"") | E5: =IFERROR(INDEX(StageGates!$J:$J,MATCH(I5,StageGates!$O:$O,0)),"") | F5: =IFERROR(INDEX(StageGates!$G:$G,MATCH(I5,StageGates!$O:$O,0)),"") | G5: =IFERROR(INDEX(StageGates!$H:$H,MATCH(I5,StageGates!$O:$O,0)),"") | H5: StageGate | I5: =A5&"|"&B5
A6: PRJ001 | B6: Build | C6: =IFERROR(INDEX(StageGates!$I:$I,MATCH(I6,StageGates!$O:$O,0)),"") | D6: =IFERROR(INDEX(StageGates!$J:$J,MATCH(I6,StageGates!$O:$O,0)),"") | E6: =IFERROR(INDEX(StageGates!$J:$J,MATCH(I6,StageGates!$O:$O,0)),"") | F6: =IFERROR(INDEX(StageGates!$G:$G,MATCH(I6,StageGates!$O:$O,0)),"") | G6: =IFERROR(INDEX(StageGates!$H:$H,MATCH(I6,StageGates!$O:$O,0)),"") | H6: StageGate | I6: =A6&"|"&B6
A7: PRJ001 | B7: Testing | C7: =IFERROR(INDEX(StageGates!$I:$I,MATCH(I7,StageGates!$O:$O,0)),"") | D7: =IFERROR(INDEX(StageGates!$J:$J,MATCH(I7,StageGates!$O:$O,0)),"") | E7: =IFERROR(INDEX(StageGates!$J:$J,MATCH(I7,StageGates!$O:$O,0)),"") | F7: =IFERROR(INDEX(StageGates!$G:$G,MATCH(I7,StageGates!$O:$O,0)),"") | G7: =IFERROR(INDEX(StageGates!$H:$H,MATCH(I7,StageGates!$O:$O,0)),"") | H7: StageGate | I7: =A7&"|"&B7
